2020-09-18 17:45:16,673 INFO: server startup[in C:\Users\itpaz\KeeperHome\keepershomeserver\app\__init__.py:57]
2020-09-18 17:45:17,920 INFO: server startup[in C:\Users\itpaz\KeeperHome\keepershomeserver\app\__init__.py:57]
2020-09-18 17:45:21,428 ERROR: cannot encode object: {'existing_skills.$'}, of type: <class 'set'> originated in route: /delete_skill [in C:\Users\itpaz\KeeperHome\keepershomeserver\app\error_handler.py:43]
2020-09-18 17:53:28,549 INFO: server startup[in C:\Users\itpaz\KeeperHome\keepershomeserver\app\__init__.py:57]
2020-09-18 17:53:29,441 ERROR: The positional operator did not find the match needed from the query., full error: {'operationTime': Timestamp(1600440808, 4), 'ok': 0.0, 'errmsg': 'The positional operator did not find the match needed from the query.', 'code': 2, 'codeName': 'BadValue', '$clusterTime': {'clusterTime': Timestamp(1600440808, 4), 'signature': {'hash': b'\xca\x0b\xf9\xd4 z\xf1F2\x19\x90=k\x04\xa0\xfa\xafY\xb5k', 'keyId': 6865241906801016835}}} originated in route: /delete_skill [in C:\Users\itpaz\KeeperHome\keepershomeserver\app\error_handler.py:43]
2020-09-18 17:54:06,659 INFO: server startup[in C:\Users\itpaz\KeeperHome\keepershomeserver\app\__init__.py:57]
2020-09-18 17:54:07,437 ERROR: 'dict' object has no attribute 'deleted_count' originated in route: /delete_skill [in C:\Users\itpaz\KeeperHome\keepershomeserver\app\error_handler.py:43]
2020-09-18 17:57:47,905 INFO: server startup[in C:\Users\itpaz\KeeperHome\keepershomeserver\app\__init__.py:57]
2020-09-18 17:58:00,388 INFO: server startup[in C:\Users\itpaz\KeeperHome\keepershomeserver\app\__init__.py:57]
2020-09-18 17:58:01,180 ERROR: Cannot use the part (Transfiguration) of (existing_skills.Transfiguration) to traverse the element ({existing_skills: [ {  Care of Magical Creatures: "4" }, { Transfiguration: "2" }, { Flying: "2" } ]}), full error: {'operationTime': Timestamp(1600441079, 1), 'ok': 0.0, 'errmsg': 'Cannot use the part (Transfiguration) of (existing_skills.Transfiguration) to traverse the element ({existing_skills: [ {  Care of Magical Creatures: "4" }, { Transfiguration: "2" }, { Flying: "2" } ]})', 'code': 28, 'codeName': 'PathNotViable', '$clusterTime': {'clusterTime': Timestamp(1600441079, 1), 'signature': {'hash': b'\xd3r\x11\xefdm\x9c\x01\xa7\xfe\x985b\x8c \x08\x99\xe6\x90T', 'keyId': 6865241906801016835}}} originated in route: /delete_skill [in C:\Users\itpaz\KeeperHome\keepershomeserver\app\error_handler.py:43]
2020-09-18 18:00:25,482 INFO: server startup[in C:\Users\itpaz\KeeperHome\keepershomeserver\app\__init__.py:57]
2020-09-18 18:03:42,217 INFO: server startup[in C:\Users\itpaz\KeeperHome\keepershomeserver\app\__init__.py:57]
2020-09-18 18:09:20,536 INFO: server startup[in C:\Users\itpaz\KeeperHome\keepershomeserver\app\__init__.py:57]
2020-09-18 18:09:24,727 ERROR: '5f588b25d1592423bfdec21' is not a valid ObjectId, it must be a 12-byte input or a 24-character hex string originated in route: /capability_add [in C:\Users\itpaz\KeeperHome\keepershomeserver\app\error_handler.py:43]
2020-09-18 18:09:47,874 ERROR: {'message': 'update failed'} originated in route: /capability_add [in C:\Users\itpaz\KeeperHome\keepershomeserver\app\error_handler.py:43]
2020-09-18 18:10:06,045 INFO: server startup[in C:\Users\itpaz\KeeperHome\keepershomeserver\app\__init__.py:57]
2020-09-18 18:10:07,443 ERROR: update failed originated in route: /capability_add [in C:\Users\itpaz\KeeperHome\keepershomeserver\app\error_handler.py:43]
2020-09-18 18:13:12,385 INFO: server startup[in C:\Users\itpaz\KeeperHome\keepershomeserver\app\__init__.py:57]
2020-09-18 18:13:22,740 INFO: server startup[in C:\Users\itpaz\KeeperHome\keepershomeserver\app\__init__.py:57]
2020-09-20 23:39:05,532 ERROR: 'skill' originated in route: /delete_skill [in C:\Users\itpaz\KeeperHome\keepershomeserver\app\error_handler.py:43]
2020-09-20 23:51:49,750 ERROR: update failed originated in route: /capability_add [in C:\Users\itpaz\KeeperHome\keepershomeserver\app\error_handler.py:43]
2020-09-20 23:54:10,624 ERROR: skill update failed originated in route: /capability_edit [in C:\Users\itpaz\KeeperHome\keepershomeserver\app\error_handler.py:43]
2020-09-23 17:12:46,848 INFO: server startup[in C:\Users\itpaz\KeeperHome\keepershomeserver\app\__init__.py:57]
2020-10-03 12:08:03,387 INFO: server startup[in C:\Users\itpaz\KeeperHome\keepershomeserver\app\__init__.py:57]
2020-10-03 12:08:04,420 INFO: server startup[in C:\Users\itpaz\KeeperHome\keepershomeserver\app\__init__.py:57]
2020-10-03 12:17:14,849 ERROR: update failed originated in route: /capability_add [in C:\Users\itpaz\KeeperHome\keepershomeserver\app\error_handler.py:43]
2020-10-03 12:18:15,290 ERROR: update failed originated in route: /capability_add [in C:\Users\itpaz\KeeperHome\keepershomeserver\app\error_handler.py:43]
2020-10-03 12:24:14,211 ERROR: update failed originated in route: /capability_add [in C:\Users\itpaz\KeeperHome\keepershomeserver\app\error_handler.py:43]
2020-10-03 12:24:16,778 INFO: server startup[in C:\Users\itpaz\KeeperHome\keepershomeserver\app\__init__.py:57]
2020-10-03 12:24:19,098 ERROR: update failed originated in route: /capability_add [in C:\Users\itpaz\KeeperHome\keepershomeserver\app\error_handler.py:43]
2020-10-03 12:24:50,490 INFO: server startup[in C:\Users\itpaz\KeeperHome\keepershomeserver\app\__init__.py:57]
2020-10-03 12:24:52,121 INFO: server startup[in C:\Users\itpaz\KeeperHome\keepershomeserver\app\__init__.py:57]
2020-10-03 12:25:00,561 ERROR: update failed originated in route: /capability_add [in C:\Users\itpaz\KeeperHome\keepershomeserver\app\error_handler.py:43]
2020-10-03 12:25:12,053 INFO: server startup[in C:\Users\itpaz\KeeperHome\keepershomeserver\app\__init__.py:57]
2020-10-03 12:25:13,752 INFO: server startup[in C:\Users\itpaz\KeeperHome\keepershomeserver\app\__init__.py:57]
2020-10-03 12:25:18,177 ERROR: update failed originated in route: /capability_add [in C:\Users\itpaz\KeeperHome\keepershomeserver\app\error_handler.py:43]
2020-10-03 12:25:47,368 INFO: server startup[in C:\Users\itpaz\KeeperHome\keepershomeserver\app\__init__.py:57]
2020-10-03 12:25:49,067 INFO: server startup[in C:\Users\itpaz\KeeperHome\keepershomeserver\app\__init__.py:57]
2020-10-03 12:28:59,032 INFO: server startup[in C:\Users\itpaz\KeeperHome\keepershomeserver\app\__init__.py:57]
2020-10-03 12:29:00,725 INFO: server startup[in C:\Users\itpaz\KeeperHome\keepershomeserver\app\__init__.py:57]
2020-10-03 12:29:16,121 ERROR: update failed database query returned None originated in route: /capability_add [in C:\Users\itpaz\KeeperHome\keepershomeserver\app\error_handler.py:43]
2020-10-04 12:32:09,875 INFO: server startup[in C:\Users\itpaz\KeeperHome\keepershomeserver\app\__init__.py:57]
2020-10-04 12:33:14,602 INFO: server startup[in C:\Users\itpaz\KeeperHome\keepershomeserver\app\__init__.py:57]
2020-10-04 12:33:16,446 ERROR: name 'student_id' is not defined originated in route: /capability_add [in C:\Users\itpaz\KeeperHome\keepershomeserver\app\error_handler.py:43]
2020-10-04 12:34:03,961 ERROR: name 'student_id' is not defined originated in route: /capability_add [in C:\Users\itpaz\KeeperHome\keepershomeserver\app\error_handler.py:43]
2020-10-04 12:36:10,167 INFO: server startup[in C:\Users\itpaz\KeeperHome\keepershomeserver\app\__init__.py:57]
2020-10-04 12:36:17,091 ERROR: update failed name 'student_id' is not defined originated in route: /capability_add [in C:\Users\itpaz\KeeperHome\keepershomeserver\app\error_handler.py:43]
2020-10-04 12:36:37,508 INFO: server startup[in C:\Users\itpaz\KeeperHome\keepershomeserver\app\__init__.py:57]
2020-10-04 12:45:14,242 INFO: server startup[in C:\Users\itpaz\KeeperHome\keepershomeserver\app\__init__.py:57]
2020-10-04 12:45:17,197 ERROR: update failed: name 'student_id' is not defined originated in route: /capability_add [in C:\Users\itpaz\KeeperHome\keepershomeserver\app\error_handler.py:43]
2020-10-04 12:46:19,331 ERROR: update failed: name 'student_id' is not defined originated in route: /capability_add [in C:\Users\itpaz\KeeperHome\keepershomeserver\app\error_handler.py:43]
2020-10-04 12:47:16,908 ERROR: update failed: name 'student_id' is not defined originated in route: /capability_add [in C:\Users\itpaz\KeeperHome\keepershomeserver\app\error_handler.py:43]
2020-10-04 12:48:42,512 ERROR: update failed: name 'student_id' is not defined originated in route: /capability_add [in C:\Users\itpaz\KeeperHome\keepershomeserver\app\error_handler.py:43]
2020-10-04 12:49:16,349 ERROR: update failed: name 'student_id' is not defined originated in route: /capability_add [in C:\Users\itpaz\KeeperHome\keepershomeserver\app\error_handler.py:43]
2020-10-04 12:49:48,731 ERROR: update failed: name 'student_id' is not defined originated in route: /capability_add [in C:\Users\itpaz\KeeperHome\keepershomeserver\app\error_handler.py:43]
2020-10-04 13:00:35,007 ERROR: update failed: name 'student_id' is not defined originated in route: /capability_add [in C:\Users\itpaz\KeeperHome\keepershomeserver\app\error_handler.py:43]
2020-10-04 13:02:04,341 ERROR: update failed: name 'student_id' is not defined originated in route: /capability_add [in C:\Users\itpaz\KeeperHome\keepershomeserver\app\error_handler.py:43]
2020-10-04 13:02:59,834 ERROR: update failed: name 'student_id' is not defined originated in route: /capability_add [in C:\Users\itpaz\KeeperHome\keepershomeserver\app\error_handler.py:43]
2020-10-04 13:03:30,857 ERROR: update failed: name 'student_id' is not defined originated in route: /capability_add [in C:\Users\itpaz\KeeperHome\keepershomeserver\app\error_handler.py:43]
2020-10-04 13:04:55,182 ERROR: update failed: name 'student_id' is not defined originated in route: /capability_add [in C:\Users\itpaz\KeeperHome\keepershomeserver\app\error_handler.py:43]
2020-10-04 13:05:50,070 ERROR: update failed: name 'student_id' is not defined originated in route: /capability_add [in C:\Users\itpaz\KeeperHome\keepershomeserver\app\error_handler.py:43]
2020-10-04 13:11:13,921 INFO: server startup[in C:\Users\itpaz\KeeperHome\keepershomeserver\app\__init__.py:57]
